File: AE2610Lab1Figure/Figure 4 - true stress and true strain.csv
True Stress (Mpa),True Strain (microstrain)
-0.003600004,0.9999995
3.599205143,56.99837556
7.990938687,129.9915507
12.3554706,199.9800027
16.67750171,269.9635566
21.04912255,347.939462
25.36989879,413.9143256
29.66761146,485.8819402
34.266181,562.841575
38.6656668,627.8028905
43.14982521,693.7592934
47.6927666,760.7105863
52.30927625,827.6573971
56.9588463,896.5979359
61.32365304,958.5404533
66.17271984,1031.467854
70.67178941,1091.404202
75.55874813,1163.323077
79.96413737,1219.256405
84.62994757,1288.169953
89.26004959,1348.090917
93.80053375,1414.998417
98.3878989,1478.905879
103.0498692,1544.806172
107.6700922,1611.700513
112.1768939,1674.597079
116.633774,1737.48969
121.2853422,1799.380144
125.6657051,1862.264908
130.1850842,1925.145717
134.1400405,1983.032491
138.3247591,2041.913874
141.1479812,2082.829404
144.8344512,2134.719863
149.0426321,2192.594507
152.8770534,2248.470295
156.9503635,2306.338356
160.5231023,2358.217219
164.6573449,2416.078929
168.302385,2469.947168
172.1258369,2524.809983
175.6928454,2579.669789
179.5821271,2637.518688
183.2265328,2693.369621
186.8610587,2746.225668
190.3617712,2801.073329
194.1077369,2859.906566
197.4202926,2914.747992
200.9676043,2974.571572
204.2062084,3036.385512
207.7714594,3104.177053
210.8061248,3162.992461
213.9559401,3223.797975
216.9706236,3286.593231
219.9286858,3354.367813
222.8504642,3424.130967
225.3201462,3492.892742
228.0935827,3570.617751
230.6088215,3652.322144
232.833051,3733.023589
235.107359,3814.714715
237.2116559,3904.368026
239.2809855,3994.013299
240.893575,4087.634228
242.7677378,4188.217161
244.3395885,4293.768568
245.8578288,4399.308835
247.15626,4501.851443
248.3772179,4611.351357
249.7179157,4733.777973
250.6623305,4846.237996
251.7146813,4962.66558
252.671887,5079.07961
253.5611158,5206.423027
254.3071418,5328.776816
255.0696839,5452.110199
255.8740378,5575.428373
256.5039113,5704.697229
257.045416,5831.961008
257.7444857,5959.208593
258.2289872,6089.42178
258.9607732,6225.580794
259.0734192,6352.778305
259.8221894,6486.914402
260.137563,6617.058897
260.7421125,6762.085479
260.8459909,6888.221636
261.4613986,7025.264937
261.7459608,7163.282322
262.0647987,7302.273386
262.3267002,7436.28219
262.7366372,7571.265496
263.0538762,7713.176824
263.3248318,7855.068015
263.4903389,7989.002765
263.9972607,8129.862925
264.0731834,8272.686771
264.4131092,8413.50698
264.5379676,8552.324394
264.9563716,8694.096577
265.1894949,8839.813467
265.2090193,8976.589594
265.5999517,9117.310721
265.7608236,9259.002832
266.0174534,9407.609349
266.0839452,9543.317341
266.3899815,9685.939469
266.6114117,9832.502129
266.7581689,9976.073096
266.9237772,10113.68385
267.1438078,10258.20425
267.3825312,10406.66236
267.5398245,10548.17191
267.5987817,10687.6827
267.9808984,10833.10941
268.0385467,10976.5368
268.3137559,11123.89938
268.2801496,11261.35228
268.7412082,11412.62751
268.7736893,11557.94883
268.9376216,11697.31883
269.0088866,11839.6341
269.3200325,11986.86956
269.4388115,12132.10746
269.5478048,12274.36088
269.6591096,12417.58171
270.0232441,12564.73211
269.9573888,12707.91137
270.2970452,12852.05736
270.2268317,12995.19549
270.7239382,13145.22175
270.5842989,13286.34433
270.9032729,13434.3536
270.9723842,13573.46235
271.2502867,13722.41551
271.2636963,13866.41535
271.4522067,14008.42228
271.6766565,14153.3669
271.8214567,14300.26211
271.8984505,14446.15009
272.0280317,14586.10369
272.1918021,14727.02308
272.48212,14877.775
272.4605459,15034.41467
272.69456,15181.18053
272.878504,15326.94006
272.9903469,15473.66299
273.1593073,15614.45738
273.1966106,15756.21631
273.6178901,15905.82894
273.4867534,16053.45105
273.7940685,16207.93884
273.8070779,16348.62989
274.1226414,16503.0721
274.1201829,16647.6556
274.3640406,16797.13493
274.5004252,16941.67593
274.6948719,17098.97572
274.7606404,17248.38761
274.9549261,17403.67368
275.0569973,17549.10964
275.337537,17708.27882
275.1734001,17846.79433
275.6505989,17995.11237
275.6404355,18135.55222
275.9467523,18282.84556
275.922176,18422.26327
276.1344361,18564.60636
276.2787169,18708.89213
276.4118545,18849.23178
276.5608476,18994.45768
276.7279153,19136.71935
276.908204,19280.9226
276.9764098,19424.1243
277.0953064,19564.36362
277.3869965,19704.58327
277.4084121,19845.76362
277.635459,19990.84488
277.6600564,20131.98482
278.0072908,20271.14498
278.097722,20413.22516
278.1006879,20555.28515
278.3297745,20694.38642
278.4570466,20832.48896
278.7158431,20977.42714
278.6614178,21114.5115
278.9961551,21257.45088
279.0821029,21394.49685
279.2045146,21541.31099
279.2808543,21679.29662
279.4942928,21813.34954
279.673475,21955.21079
279.8228147,22100.96449
279.8509025,22232.02686
280.2304441,22375.78447
280.1461664,22531.25415
280.4469348,22673.0136
280.3548682,22804.00102
280.8132036,22948.65375
280.7109555,23090.35405
280.9970544,23233.01131
281.0088013,23365.87921
281.3100815,23507.5204
281.4002688,23650.11816
281.5128168,23785.86015
281.6530064,23922.56008
281.8833787,24065.09867
281.9290553,24208.59303
282.12261,24345.23519
282.1752609,24479.90704
282.507913,24624.31758
282.450485,24759.9274
282.7354576,24898.44506
282.8341528,25034.993
283.0126626,25177.37312
283.1013504,25313.88298
283.1668934,25446.47471
283.518532,25589.771
283.5328808,25730.12297
283.6519817,25864.60846
283.7460618,25999.07587
283.9794049,26141.31881
284.1446567,26279.64527
284.180807,26416.97867
284.3778017,26553.31943
284.5895007,26713.00924
284.7320513,26852.23016
284.8066097,26988.51158
284.9034434,27125.74768
285.2391574,27264.91115
285.1756089,27399.1904
285.4571459,27535.39731
285.5002395,27671.58567
285.816713,27811.64578
285.7462033,27944.87921
285.9575202,28082.95644
286.1316064,28219.07025
286.3124586,28357.10962
286.3283017,28492.21422
286.515474,28627.30057
286.6634567,28766.25525
286.9591478,28906.16213
286.7932284,29038.27844
287.1946042,29179.11852
287.1985879,29310.22766
287.5209826,29452.00042
287.3841722,29580.16124
287.7257896,29722.86645
287.8141701,29857.78667
287.9770356,29993.65913
288.0316636,30131.45378
288.2026511,30266.31888
288.4276769,30405.04602
288.4767011,30538.90431
288.5910734,30673.71448
288.8202343,30812.38511
288.8105966,30950.06699
288.9759451,31089.6687
289.0112728,31231.18943
289.2779286,31369.78279
289.4577387,31512.23286
289.4049237,31651.75612
289.7042461,31793.19732
289.746707,31929.77567
290.1461555,32076.01974
289.9199191,32213.52776
290.2700934,32356.82587
290.3376678,32491.3912
290.5948299,32636.58528
290.5533728,32773.04849
290.8583435,32915.29882
290.9711772,33052.6915
291.1201158,33196.83676
291.1161469,33331.28911
291.466209,33469.59173
291.5233358,33662.02299
291.7436911,33805.11369
291.645079,33936.5844
292.109981,34079.63582
292.0740406,34215.90226
292.2964975,34356.01506
292.2275215,34485.48116
292.5150784,34624.59022
292.6494209,34761.74827
292.695958,34895.99039
292.8662015,35032.14565
293.0428267,35167.31692
293.1327257,35304.40056
293.2786975,35437.60468
293.3135124,35570.79105
293.6811674,35708.78431
293.6387778,35842.89937
293.8227668,35976.99645
293.9135401,36109.14648
294.1472618,36243.20786
294.2057018,36390.75105
294.2338906,36518.98986
294.5395514,36654.92433
294.6276271,36786.98481
294.7900581,36920.95535
294.751335,37050.08982
295.060999,37186.91562
295.1977784,37320.8326
295.2153032,37450.87869
295.3237772,37580.90787
295.6473485,37717.66106
295.6692165,37849.58127
295.8338224,37984.37228
295.7868471,38119.14511
296.2491081,38301.05963
296.1183369,38437.71438
296.4152555,38572.42614
296.352514,38702.30957
296.7399386,38841.79522
296.6292429,38972.60545
296.8673076,39106.28353
296.9246455,39237.05917
297.2055146,39375.50886
297.1712146,39507.21057
297.3127302,39635.05038
297.4724548,39767.67892
297.7117986,39905.0943
297.6372774,40034.80477
297.8767388,40166.41968
297.9419693,40298.01727
298.2794191,40444.00309
298.176251,40573.64368
298.3797545,40704.22759
298.6327817,40838.63438
298.6547371,40971.1034
298.7564761,41104.51461
298.8099294,41232.15039
299.1441401,41368.40521
299.1022881,41502.72277
299.2169987,41633.18542
299.3289924,41764.59014
299.501506,41938.17136
299.6639226,42069.53602
299.6960091,42199.92474
299.9673111,42334.13067
300.068787,42469.27701
300.1698365,42605.36337
300.2418322,42735.68225
300.3990924,42870.77434
300.607721,43006.80608
300.562676,43135.1571
300.8312986,43271.15288
300.878445,43404.25761
301.1276036,43541.1742
301.0680003,43682.85834
301.2402009,43816.86541
301.3919812,43949.89753
301.5562322,44086.73944
301.5320058,44217.82217
301.8249757,44350.80095
301.8326244,44486.63153
302.095005,44621.4873
301.9657441,44750.58748
302.3985196,44887.31988
302.3174708,45020.20967
302.579361,45155.94936
302.4765541,45287.84774
302.8758666,45425.46228
302.8938102,45562.10244
302.9215255,45692.99193
303.0666075,45847.74426
303.2051153,45982.41661
303.3845703,46118.02576
303.41473,46248.84251
303.5723715,46383.46086
303.8109767,46519.97018
303.7429731,46651.68878
303.9318681,46788.1615
304.0666604,46918.89062
304.2393247,47053.4188
304.3583828,47190.79062
304.3113212,47322.42089
304.6965824,47457.84846
304.7487836,47596.11825
304.8204402,47732.46214
304.7153191,47857.34828
305.1124041,47998.42225
305.0658501,48147.10031
305.1982357,48286.22769
305.2944168,48417.71387
305.5412704,48556.80361
305.6121268,48691.11164
305.6814206,48837.78208
305.7398193,48971.10018
306.1028866,49110.11298
306.0484329,49242.44283
306.2355818,49379.51428
306.2406296,49509.90509
306.5636903,49647.89145
306.4586425,49789.6645
306.6511837,49925.70967
306.7848569,50058.88281
306.9375393,50193.94032
306.9752521,50327.07775
307.0305283,50460.19746
307.2305491,50593.29945
307.4091623,50730.18587
307.3330306,50877.50796
307.5831266,51019.1068
307.7123381,51156.88508
307.9236434,51291.79439
307.7989966,51424.78574
308.0455618,51557.75941
308.1540569,51693.56427
308.3180504,51830.30017
308.3241926,51962.27057
308.4360945,52094.22356
308.6692527,52231.8538
308.6212245,52364.72021
308.7710951,52497.56896
308.882463,52628.5026
309.1391187,52767.95654
309.1332923,52903.59715
309.2089144,53032.58095
309.4173929,53167.23746
309.5319612,53300.92774
309.482959,53433.65219
309.7419779,53567.30686
309.7961641,53699.99596
310.089199,53840.24815
309.8429912,53966.26881
310.2442262,54104.58899
310.1967827,54233.41799
310.46686,54373.59539
310.2754624,54498.6019
310.6137524,54633.06115
310.6775082,54766.55563
310.8395786,54901.92544
310.8007056,55033.49112
311.002954,55165.0395
311.152523,55300.35538
311.2128044,55435.65296
311.2229299,55564.3106
311.5449521,55701.46412
311.5490446,55835.76174
311.6829919,56001.24458
311.6636954,56140.229
311.9305866,56277.30355
312.0238997,56410.57873
311.9928307,56541.94608
312.1889619,56673.29619
312.2971927,56808.40815
312.4664999,56944.44651
312.4031598,57074.79923
312.5257465,57208.91256
312.7494076,57342.06364
312.8064279,57474.25285
312.8872866,57606.42458
313.0346214,57741.41053
313.2467029,57877.32203
313.2226616,58011.32778
313.2408914,58145.31558
313.5345518,58295.32287
313.5537366,58430.21587
313.7629407,58568.86313
313.599533,58699.0043
314.0003166,58842.32859
313.9870643,58981.86146
314.0654856,59115.71929
314.0949241,59243.90436
314.3110546,59379.61182
314.4340261,59516.24309
314.4598998,59648.14522
314.523328,59780.97193
314.8194925,59918.49021
314.7263959,60053.16445
314.9432931,60186.87896
314.8992239,60335.63889
315.2503476,60478.72882
315.1466243,60616.15119
315.3274607,60747.90833
315.3555916,60880.58905
315.56286,61016.0746
315.6077154,61152.48247
315.5805125,61283.22842
315.8327335,61418.65943
315.9110247,61554.0721
316.0070037,61688.52626
316.0416835,61820.14219
316.2641167,61957.38036
316.3382499,62090.84051
316.2776418,62225.22252
316.4528023,62357.70739
316.6641031,62493.93239
316.718097,62630.13883
316.836068,62762.57007
316.7841647,62892.16664
317.1466439,63031.1356
317.0067595,63160.69737
317.2325529,63299.62903
317.2304936,63429.15602
317.4408186,63567.11197
317.4447293,63701.29576
317.5447124,63833.58523
317.6810198,63967.73327
317.8458612,64104.67704
317.8318049,64236.91316
317.9778764,64371.00711
318.0664407,64506.95814
318.2904981,64642.89069
318.1404375,64774.11838
318.4214379,64909.07747
318.413183,65044.01835
318.6732878,65181.75172
318.5340837,65311.03517
318.7439655,65448.73177
318.8816056,65581.72681
318.8861645,65716.57696
318.9749421,65848.60011
319.0736228,65982.47813
319.2496655,66121.01833
319.3523617,66253.92399
319.3243792,66386.812
319.5705626,66522.48927
319.5156835,66658.14814
319.781308,66792.85322
319.6911349,66928.47542
319.9437193,67070.62515
319.978031,67209.94969
320.0059219,67349.25482
320.1321678,67486.67107
320.1842678,67620.32998
320.4101116,67755.84001
320.315382,67885.72549
320.5759395,68022.13381
320.6146775,68156.65529
320.7589183,68293.96064
320.7532086,68424.71011
320.8359897,68558.24372
320.959912,68691.75949
321.1441664,68829.92488
321.0483296,68970.87124
321.4079075,69109.9313
321.2578507,69245.23964
321.5403804,69383.32858
321.3600921,69512.07001
321.7839947,69650.12212
321.6051253,69780.69441
321.8232901,69916.84449
321.8131765,70047.38196
322.0264269,70185.36019
322.0924641,70321.4552
322.1150882,70478.9667
322.2035399,70611.29447
322.4251788,70749.19491
322.4302,70884.28164
322.5594265,71019.35012
322.5791517,71163.7135
322.8279346,71308.05604
322.6893846,71442.13625
322.9015113,71580.85311
322.987642,71715.82754
323.0527881,71852.6451
323.1728741,71997.81877
323.1165445,72131.80654
323.4068135,72267.63692
323.3734401,72403.44885
323.4271819,72542.03242
323.5064361,72675.01739
323.6990809,72811.70379
323.8113275,72947.44186
323.7554216,73079.4434
323.9697911,73215.14513
324.0545142,73351.75772
324.174119,73488.35166
324.1665571,73623.06889
324.2317136,73754.98129
324.4876852,73895.23524
324.3464272,74028.04039
324.5911525,74163.61346
324.523674,74294.52618
324.8400386,74432.84795
324.6988987,74566.50987
324.8965589,74702.00996
324.9564653,74835.63591
325.0971063,74973.88286
325.0262927,75106.54484
325.2037617,75256.81198
325.2609548,75392.21858
325.5614933,75530.38861
325.3241182,75662.97679
325.6111094,75797.40141
325.6237828,75932.73483
325.8869564,76069.90345
325.6698043,76199.64023
325.9138186,76336.77225
325.9707724,76471.10632
326.0596208,76608.20112
326.2070701,76742.49874
326.1584797,76874.92632
326.4111107,77015.66927
326.3640666,77146.20918
326.4145942,77284.13708
326.5829852,77418.34396
326.7024991,77555.30897
326.7372996,77692.25522
326.6974287,77823.63196
326.8993927,77958.69147
327.0548191,78097.43224
326.9233469,78228.75576
327.1628063,78368.3837
327.1165664,78502.44515
327.4358013,78642.95925
327.1853754,78773.28692
327.460856,78913.76296
327.4907098,79045.90334
327.5998534,79184.49336
327.5756493,79313.82672
327.7899834,79450.53237
327.9246888,79586.29584
327.9512063,79722.96425
327.9373623,79857.7675
328.1203343,79992.55257
328.1641878,80129.16547
328.3311512,80278.67983
328.1589009,80416.17639
328.5495396,80554.57665
328.4660517,80691.1128
328.6254722,80828.55266
328.5082501,80959.51804
328.7774661,81095.99892
328.8705341,81235.22711
328.8203,81366.13924
328.9182565,81505.32983
329.0953265,81649.10903
329.1451807,81791.02463
329.1933692,81925.5494
329.149398,82060.05607
329.4784135,82200.0712
329.363885,82338.2248
329.5479294,82481.88431
329.5560662,82616.31618
329.784812,82755.33287
329.7493931,82889.72799
329.6501712,83024.10504
329.9809011,83159.38425
329.9637589,83296.48532
330.0829973,83434.48754
329.9538663,83566.95176
330.2956157,83707.67577
330.3106464,83844.7017
330.3234712,83982.62829
330.3312196,84118.69722
330.5647172,84258.42442
330.6115146,84395.3749
330.7230608,84532.30663
330.6305809,84668.3008
330.9708267,84809.7886
330.7626738,84942.98935
331.0311899,85082.60143
330.888152,85213.0109
331.2850706,85355.33985
331.14041,85488.46795
331.2487606,85626.16803
331.2898627,85761.09571
331.4838205,85901.51132
331.4607948,86034.56673
331.5252316,86169.43933
331.6553635,86306.12836
331.845439,86444.63309
331.7030154,86581.28451
331.9001095,86715.16646
331.8641091,86850.86411
332.1633735,86992.96015
331.9406574,87125.87044
332.1725188,87260.59593
332.2699332,87397.13591
332.3493697,87537.32199
332.3226454,87675.65631
332.3493188,87808.47589
332.5934874,87950.43594
332.5844227,88085.0504
332.6139621,88221.47786
332.7244425,88357.88671
332.7899219,88498.85348
332.9039682,88637.97004
332.8766109,88768.83176
333.0764277,88909.74062
333.1778654,89047.88523
333.1400806,89184.18141
333.2111394,89317.71535
333.2698173,89456.71804
333.5413464,89621.30151
333.2758406,89751.12046
333.5958357,89891.89099
333.5589215,90026.24437
333.7973098,90169.71751
333.6461209,90304.03357
333.8552319,90442.89924
333.8962486,90580.83223
333.9869517,90719.65947
333.9341061,90853.90169
334.1783069,90990.86498
334.1706333,91131.46111
334.3570787,91272.03747
334.1061704,91403.46762
334.5564224,91547.65583
334.3831926,91681.78696
334.5909997,91825.93505
334.5056647,91962.76528
334.7124804,92100.4888
334.7406525,92240.01713
334.7481379,92377.70247
334.8444641,92515.36887
334.958615,92655.75083
335.0824881,92794.29033
334.9595663,92929.16562
335.1598365,93067.66725
335.3181223,93209.79372
335.2859969,93346.43474
335.3324664,93483.05709
335.3979819,93617.83951
335.5633893,93758.97731
335.6194004,93901.00557
335.4969125,94033.91117
335.8469676,94178.63075
335.7141588,94314.22946
335.8883185,94456.17889
335.7156006,94589.92048
336.1038044,94732.74039
336.0478612,94872.81145
336.0925334,95011.95352
336.109037,95147.43929
336.3083365,95287.45227
336.3633173,95428.35464
336.3481509,95567.41944
336.4065865,95706.46491
336.6580443,95846.39965
336.499141,95984.49786
336.702951,96154.36883
336.6245508,96293.33271
336.9429032,96435.90957
336.7369106,96572.11051
336.9292387,96713.73981
336.9880453,96852.62599
337.0800818,96993.308
337.1097325,97134.87767
337.1620715,97272.79806
337.3229406,97412.51381
337.4325272,97554.02414
337.3080437,97695.51445
337.4493209,97831.54395
337.5024861,97972.08833
337.7254045,98117.14568
337.5390111,98252.21142
337.7738509,98394.50928
337.8296867,98534.97456
337.8698022,98677.23219
337.8771707,98814.03413
337.8983036,98951.72315
338.2125415,99131.05278
338.0610451,99274.13114
338.2099479,99416.28366
338.2178524,99552.98455
338.4087706,99703.24343
338.3608944,99847.14492
338.4536935,99986.50148
338.5430028,100128.5528
338.6377154,100271.4885
338.5750419,100408.977
338.7400353,100553.6813
338.7528759,100694.7479
339.0178549,100841.219
338.7278869,100975.9173
339.0508251,101120.5397
339.0107094,101259.7189
339.2190702,101405.2037
339.0034918,101540.7296
339.2508164,101683.4636
339.3218816,101827.9836
339.4224681,101974.2889
339.3588026,102109.7376
339.5517073,102250.5848
339.6243516,102395.0229
339.6572521,102538.5376
339.5407575,102674.8124
339.8670515,102820.0915
339.8498832,102962.6431
339.9153725,103106.0763
339.8298136,103243.1757
340.0553342,103385.6669
340.1167946,103530.8428
339.9993261,103668.7855
340.1651032,103812.1175
340.2536306,103953.6265
340.4321469,104099.6211
340.2738169,104239.2873
340.4107797,104379.8349
340.5415153,104532.9733
340.5577329,104680.6846
340.5888639,104819.3693
340.7245093,104961.6361
340.8762393,105109.2841
340.8470393,105252.4098
340.7398634,105390.1152
340.9954933,105535.0004
340.9527767,105675.3661
341.1120247,105822.9087
340.9317805,105958.7367
341.2911912,106106.2375
341.2511904,106247.4222
341.3367423,106392.1833
341.2658377,106531.5298
341.4897652,106677.1485
341.527387,106821.8474
341.5618553,106960.2354
341.5644361,107103.9949
341.8222199,107260.3099
341.7150356,107411.2115
341.8580142,107554.9062
341.7341993,107694.0908
342.0964056,107841.3359
341.9014612,107984.9688
342.1316791,108130.3761
342.0571166,108273.9674
342.2307502,108420.23
342.175158,108565.574
342.196763,108704.6179
342.3932788,108851.7143
342.4600877,108996.9956
342.5135177,109142.2559
342.4673064,109281.2196
342.6233367,109430.9203
342.7358529,109577.9099
342.6597593,109718.6054
342.7383257,109862.8649
342.887171,110008.8952
342.9032153,110154.0085
342.9640263,110302.683
342.8852984,110449.5446
343.2139683,110615.1857
343.0411594,110758.4207
343.2398957,110905.2154
343.1524966,111048.4089
343.4243416,111196.0557
343.366088,111342.7861
343.4320614,111491.284
343.472185,111633.4993
343.6892692,111784.6367
343.6060198,111931.2808
343.6739942,112077.0094
343.7181159,112223.6107
343.9002532,112375.5526
343.6890729,112516.7486
343.9574971,112665.9658
343.9087435,112811.5873
344.1312892,112962.5469
343.9410539,113119.7349
344.1787602,113270.6479
344.1865682,113417.967
344.3366918,113567.0498
344.2786717,113712.5402
344.3487581,113859.7942
344.4310919,114009.7034
344.5658945,114159.59
344.4621563,114305.8863
344.6712005,114455.7285
344.6240201,114602.8732
344.7936398,114752.671
344.6983097,114899.7719
344.8814234,115049.5252
345.018961,115201.0385
344.8874095,115348.9646
344.9764687,115500.4325
345.0343621,115667.9115
345.2691185,115821.1123
345.0758443,115964.4942
345.3403733,116122.1015
345.2772346,116268.111
345.4176751,116423.0001
345.370649,116569.8556
345.4968545,116717.5794
345.5642922,116868.8401
345.6165288,117020.9676
345.5946802,117169.5142
345.7842344,117320.7066
345.6985683,117473.6545
345.9015423,117628.357
345.713702,117774.1467
346.0642161,117928.8028
345.9349643,118077.2146
346.1093023,118232.7123
346.0404353,118381.079
346.2526,118540.9706
346.2488201,118698.1723
346.2892906,118851.7977
346.3147552,119002.736
346.4667135,119157.2022
346.4863641,119313.4196
346.5325568,119464.2882
346.5246179,119616.0214
346.7770425,119771.28
346.6449474,119923.8536
346.7414389,120077.2907
346.7379426,120229.8176
346.8544405,120382.3213
346.9002152,120538.3474
346.8458384,120689.9177
347.1133331,120845.8959
347.0935459,121001.8497
347.1216787,121158.6651
347.107798,121309.2557
347.2635334,121465.1373
347.3937154,121622.7656
347.2653512,121803.3876
347.4552962,121970.6996
347.5229098,122131.7883
347.5813607,122296.3907
347.5948035,122452.1185
347.5691203,122607.8221
347.8147157,122767.9238
347.8151142,122924.4625
347.8834675,123080.9767
347.8060689,123239.2346
348.1200426,123404.5387
347.9077583,123559.2103
348.0695956,123718.2761
348.1098049,123873.7827
348.276236,124035.4485
348.2153001,124195.3218
348.2730687,124353.4034
348.2816189,124513.2259
348.5903573,124675.6712
348.309939,124834.5596
348.5606468,124996.0702
348.4964667,125151.3782
348.766243,125329.5997
348.5153826,125483.0918
348.7207928,125646.2615
348.8123431,125807.6411
348.8653558,125971.6396
348.8560087,126128.5591
348.8978748,126289.8609
349.1333951,126455.5427
349.0445329,126616.7918
349.1191681,126778.8957
349.1903083,126937.4503
349.3275184,127105.6668
349.2901181,127266.811
349.2785393,127426.1686
349.4062169,127591.6623
349.5038063,127757.1286
349.3862163,127918.1679
349.5732105,128090.6184
349.5666371,128254.2429
349.7739778,128422.2381
349.5847135,128584.0497
349.7899931,128750.2311
349.8506871,128914.6267
349.9787638,129084.2688
349.8848879,129246.8521
349.9892079,129412.9234
350.1432672,129582.4809
350.131449,129746.7399
350.0587771,129914.4845
350.2848685,130080.4449
350.277931,130249.8894
350.3443766,130418.4274
350.1814232,130581.6715
350.5712542,130753.6633
350.4221963,130918.6073
350.5701224,131090.5412
350.4202909,131255.4296
350.7354513,131426.4287
350.74012,131602.6588
350.747497,131776.2282
350.7769382,131945.3856
350.9656261,132118.8955
350.9431566,132293.2514
350.9615899,132463.1973
350.9121844,132633.1143
351.2250103,132808.2562
351.0563513,132980.741
351.1559689,133153.1961
351.1896982,133322.1207
351.3738888,133503.2672
351.3659993,133678.2568
351.2664274,133849.717
351.4793471,134025.5205
351.4885621,134200.4188
351.6137924,134379.6577
351.441192,134549.2494
351.780734,134731.0478
351.7654797,134910.1916
351.7446978,135103.2816
351.6931344,135284.1057
351.9439782,135464.0239
351.9386555,135644.7828
351.9099399,135825.5091
351.8651052,136001.8386
352.1831508,136185.9911
352.005553,136365.747
352.2014135,136546.3431
352.0480894,136724.2899
352.3881016,136913.5417
352.26545,137094.0389
352.3471558,137277.1186
352.3888993,137458.4217
352.5208066,137648.4061
352.4505725,137836.6119
352.4541731,138017.8136
352.5958542,138210.3044
352.7303286,138402.7582
352.5631474,138588.2103
352.6869644,138774.4985
352.7096841,138960.7519
352.8960146,139155.6717
352.6698226,139340.1143
352.8507193,139528.002
352.9380161,139719.3328
353.0061127,139910.627
353.0048026,140102.7539
352.9307478,140289.6292
353.160726,140488.6348
353.0694277,140691.9446
353.1118096,140885.6586
353.1749873,141074.993
353.2671824,141274.7106
353.1923538,141469.1799
353.1765767,141663.6113
353.3157272,141858.8727
353.3614973,142060.169
353.2615001,142257.0878
353.3821788,142453.1006
353.3626696,142650.8091
353.5502571,142854.5466
353.2928056,143052.1758
353.5313728,143251.499
353.4965205,143454.2479
353.5816116,143658.688
353.424804,143857.8903
353.5985406,144070.0405
353.6075228,144276.0861
353.6187896,144482.0893
353.452458,144681.993
353.6354882,144886.1823
353.5532546,145094.6547
353.666039,145303.0836
353.3939302,145506.2816
353.7193735,145715.4891
353.505487,145922.0603
353.609261,146136.3651
353.4658653,146339.3939
353.6444911,146551.882
353.6363202,146765.1884
353.4393908,146976.7227
353.5195308,147184.7598
353.5149123,147412.6013
353.5160141,147631.7635
353.363612,147845.7023
353.4213876,148058.733
353.4407814,148276.0292
353.2458825,148493.2783
353.2584797,148705.3092
353.2352894,148919.8802
353.2023899,149139.5738
353.1438487,149366.9704
352.9407143,149579.6773
353.1354877,149800.0868
352.9320543,150022.1692
352.9144873,150247.6443
352.6512471,150460.164
352.8434909,150688.1207
352.6339746,150910.0059
352.4816525,151134.4212
352.41965,151364.8029
352.4146024,151595.1315
352.2080108,151823.6888
352.0520495,152047.8991
351.8863428,152269.4829
351.9971709,152497.0276
351.5987842,152728.8123
351.5536106,152956.2525
351.3527403,153180.2091
351.3894365,153422.9866
350.8728172,153657.1295
350.8868399,153885.216
350.7268396,154114.1077
350.58682,154350.6598
350.2577623,154590.5831
350.0289796,154819.3134
349.9814949,155058.2678
349.6959378,155300.5899
349.1536687,155538.5734
349.1755055,155774.7888
348.8597258,156015.2262
348.6147787,156264.1591
348.03738,156504.4789
348.0354293,156751.5803
347.7006538,157002.8941
347.1445514,157256.7083
346.9210413,157497.6439
346.5330075,157741.9378
346.2737438,158003.2491
345.5460145,158270.4676
345.3397898,158521.4
344.8408095,158771.4163
344.3520385,159034.1648
343.7115116,159287.4639
343.2670959,159530.4685
342.7989958,159789.6083
342.0738795,160052.9414
341.306979,160308.5384
340.8308301,160565.7733
340.0846765,160822.0907
339.4334749,161091.1106
338.35468,161340.4854
337.883448,161605.1121
336.7786986,161867.9677
335.9908295,162138.4071
334.9087051,162391.7714
334.0390489,162656.97
332.8769583,162929.7451
331.647176,163199.8976
330.5113237,163464.8819
329.3404271,163736.5879
327.8643148,164018.4047
326.527078,164292.5058
324.9685283,164564.8352
323.5703507,164843.8747
321.7607969,165132.162
320.0800519,165420.3663
318.071446,165707.6402
316.1285827,166010.9254
313.9226674,166314.1186
311.5429578,166612.1409
309.0859526,166931.231
305.3762183,167281.5203
196.2168053,170767.5658
177.7676961,171061.7356