File: AE2610Lab1Figure/Figure 2 - engineering stress and extensometer strain microstrain.csv
Extensometer Strain (1e-6),Engineering Stress (MPa)
-2,0.00138
7,0.15045
26,0.28116
42,0.35173
63,0.56536
81,1.0588
109,2.75696
147,5.14118
193,7.98992
246,11.25265
297,14.52485
350,17.76504
401,21.13207
454,24.60094
508,28.10829
558,31.52413
610,35.04227
663,38.62756
715,42.15613
764,45.59283
818,49.15319
868,52.56055
918,56.1198
965,59.34104
1015,62.66732
1066,66.22255
1117,69.88324
1165,73.16911
1208,76.18499
1255,79.34863
1302,82.72562
1353,86.078
1400,89.14539
1443,92.2578
1477,94.61436
1520,97.52437
1563,100.51169
1607,103.55458
1653,106.64403
1693,109.47018
1727,111.92615
1764,114.39609
1804,117.15771
1846,120.01202
1886,122.65988
1926,125.3073
1962,127.92026
1999,130.47452
2039,133.0038
2075,135.57646
2113,138.27837
2119,138.52614
2041,133.12291
1986,129.39139
1933,125.57471
1874,121.60128
1816,117.6589
1767,114.00568
1715,110.34383
1658,106.50665
1608,102.69012
1554,98.98215
1503,95.35298
1450,91.593
1396,87.78513
1344,84.17088
1294,80.59103
1241,76.87402
1188,73.07124
1138,69.49316
1091,66.01637
1037,62.35728
986,58.61044
933,54.91973
886,51.4635
836,47.90816
781,44.29734
732,40.69176
683,37.19179
635,33.62164
582,30.0015
534,26.59557
487,23.36362
437,20.02361
388,16.66314
334,13.21566
284,10.3071
240,7.37339
196,4.41131
180,3.49555
236,7.40742
286,10.59082
336,13.91758
387,17.38594
436,20.85312
487,24.18172
535,27.57714
587,31.18114
638,34.93077
689,38.43018
738,41.88467
786,45.48033
841,49.27755
890,52.93472
942,56.44488
992,60.08467
1047,63.83444
1101,67.55136
1150,71.09931
1200,74.74729
1253,78.48597
1307,82.19238
1357,85.71029
1408,89.29169
1464,93.10854
1517,96.88304
1568,100.46256
1620,103.96414
1672,107.64939
1725,111.44908
1777,115.07814
1831,118.73486
1885,122.37056
1937,125.98946
1989,129.5262
2039,133.05357
2092,136.70906
2143,140.30562
2184,143.24474
2222,145.74507
2260,148.27486
2293,150.67355
2329,153.01761
2358,155.08582
2391,157.25522
2425,159.67184
2465,162.14427
2499,164.46986
2531,166.81093
2567,169.18938
2600,171.54016
2633,173.67192
2664,175.93918
2700,178.34543
2735,180.72054
2768,182.94019
2799,184.90851
2832,187.08113
2866,189.46402
2898,191.71201
2932,193.89056
2967,196.01329
3072,198.09999
3097,200.12628
3130,202.15451
3165,204.3166
3201,206.42723
3230,208.16022
3253,209.65842
3284,211.38934
3320,213.31163
3354,215.29822
3382,216.88367
3416,218.47394
3450,220.25278
3487,222.06274
3522,223.77766
3564,225.60547
3606,227.47125
3648,229.28665
3692,230.89149
3735,232.44624
3783,234.18095
3831,235.91347
3882,237.42451
3930,238.7074
3983,240.13783
4040,241.72054
4095,243.20503
4154,244.46965
4213,245.72646
4273,246.87338
4340,248.00194
4404,249.08748
4471,250.21793
4547,251.46463
4617,252.36263
4686,253.03528
4755,253.84587
4840,254.82108
4923,255.82825
5002,256.45923
5076,257.03903
5158,257.69653
5240,258.45792
5324,259.05295
5411,259.62149
5498,260.2926
5589,260.90408
5674,261.19257
5760,261.56219
5863,262.11273
5967,262.75562
6074,263.25583
6162,263.42609
6254,263.66556
6348,264.16211
6452,264.59131
6546,264.89972
6644,265.25549
6739,265.54251
6836,265.77478
6934,266.00742
7034,266.28171
7136,266.75281
7238,267.01236
7336,267.04239
7436,267.21268
7539,267.48157
7644,267.91156
7748,268.06375
7847,268.15448
7951,268.30026
8057,268.56543
8164,268.73785
8263,268.82861
8370,269.11044
8478,269.40756
8582,269.45761
8687,269.40903
8789,269.58435
8901,269.90689
9013,270.20511
9117,270.16556
9221,270.12674
9346,270.35922
9457,270.62775
9564,270.76318
9682,270.8653
9788,270.99072
9901,271.09396
10016,271.13449
10125,271.28952
10236,271.51706
10348,271.75116
10456,271.65955
10560,271.65591
10671,271.8327
10783,272.13004
10896,272.26932
11004,272.25632
11117,272.29959
11225,272.45596
11339,272.55576
11473,272.60983
11586,272.75821
11699,273.02509
11809,273.04834
11914,272.92862
12023,273.03308
12134,273.28857
12248,273.61441
12358,273.51614
12469,273.41245
12577,273.55829
12686,273.7583
12797,273.96616
12907,273.96649
13019,274.0838
13126,274.11948
13235,274.16635
13348,274.26764
13460,274.46204
13572,274.69952
13680,274.64819
13787,274.5369
13898,274.67389
13940,274.24945
13972,272.22073
13985,271.01636
13995,270.1694
13996,269.82968
13936,265.13577
13883,261.27777
13828,257.3577
13768,253.38312
13712,249.64674
13660,246.08989
13603,242.3419
13548,238.42802
13491,234.63081
13437,231.08064
13383,227.55487
13325,223.83067
13269,220.08821
13220,216.54378
13165,213.03394
13111,209.44011
13058,205.86305
13007,202.4097
12954,198.90259
12899,195.30646
12844,191.75638
12792,188.41838
12741,185.045
12690,181.53119
12635,177.95671
12583,174.50993
12535,171.29659
12485,167.9529
12429,164.43285
12376,160.9501
12327,157.67357
12275,154.35359
12222,150.92807
12172,147.63469
12125,144.4621
12074,141.17729
12021,137.72166
11969,134.34035
11921,131.3472
11874,128.1927
11823,124.89107
11769,121.44157
11720,118.20075
11673,115.12377
11623,111.96186
11573,108.79532
11526,105.52139
11477,102.52101
11430,99.42919
11382,96.36234
11338,93.53943
11293,90.60611
11246,87.5928
11195,84.38493
11151,81.29032
11106,78.52013
11060,75.61993
11014,72.53944
10964,69.36406
10919,66.5311
10872,63.54617
10825,60.53526
10779,57.60838
10737,54.72532
10689,51.81131
10641,48.71293
10592,45.57415
10551,42.8716
10510,40.13599
10465,37.19613
10415,34.05443
10369,31.10084
10324,28.33835
10285,25.54601
10238,22.69516
10195,19.81107
10153,17.04719
10111,14.24375
10068,11.48554
10030,8.95934
9992,6.48572
9956,3.96706
9945,3.1305
9945,3.60358
9947,3.9155
9952,4.18349
9974,5.93629
10019,9.55152
10064,13.02351
10110,16.39918
10153,19.75874
10200,23.24914
10249,26.88714
10299,30.40016
10347,33.83523
10397,37.35868
10447,41.07394
10498,44.62935
10547,48.08412
10594,51.59489
10645,55.27731
10700,58.93662
10750,62.35097
10800,65.88174
10855,69.58128
10909,73.29113
10959,76.7449
11010,80.14536
11059,83.70603
11118,87.60995
11170,91.14675
11220,94.55823
11272,98.00216
11326,101.66376
11382,105.26832
11433,108.81595
11486,112.33823
11538,115.79548
11588,119.19318
11639,122.55211
11692,126.02473
11745,129.71782
11796,133.03093
11844,136.20805
11894,139.40469
11946,142.80553
11997,146.17235
12046,149.31047
12091,152.38197
12138,155.55547
12189,158.77095
12236,161.86647
12283,164.95961
12335,168.20926
12383,171.55775
12432,174.4995
12477,177.42964
12526,180.56067
12577,183.91391
12627,187.19211
12672,190.04907
12718,193.02382
12768,196.15231
12819,199.31729
12865,202.3817
12912,205.38922
12962,208.40759
13006,211.3176
13053,214.21362
13099,217.23227
13149,220.40775
13196,223.46654
13243,226.22707
13290,229.0952
13338,232.09993
13386,235.21164
13436,238.14897
13485,240.98074
13533,243.88715
13580,246.78514
13628,249.58163
13676,252.32961
13726,255.11797
13777,257.98166
13823,260.49026
13869,262.79309
13918,265.21106
13968,267.67029
14024,270.04758
14073,271.86963
14125,273.4577
14182,275.02365
14246,276.38654
14318,277.39282
14396,278.00681
14480,278.45804
14567,278.57254
14655,278.51926
14752,278.45853
14853,278.46774
14954,278.52878
15052,278.3201
15165,278.09314
15265,278.01553
15370,278.10797
15472,278.08771
15573,277.98441
15674,277.96707
15780,277.95035
15881,277.88916
15985,277.86258
16087,277.8988
16198,278.04861
16312,277.96008
16415,277.76328
16523,277.8136
16634,278.03912
16749,278.23563
16878,278.13721
16989,277.94293
17095,278.00482
17210,278.26205
17327,278.3324
17441,278.30923
17555,278.35843
17664,278.4169
17778,278.42133
17895,278.43683
18009,278.61166
18123,278.80176
18233,278.76181
18342,278.62552
18457,278.72034
18570,278.94052
18690,279.07187
18799,279.08359
18913,279.10175
19026,279.16165
19137,279.20102
19249,279.2319
19362,279.3717
19480,279.6398
19595,279.68567
19702,279.44394
19813,279.47858
19928,279.73837
20045,280.02835
20160,280.04294
20266,279.86926
20379,279.90958
20494,280.10733
20606,280.2496
20719,280.30316
20830,280.37061
20945,280.49304
21055,280.49051
21163,280.43082
21276,280.59641
21390,280.83948
21504,280.96021
21609,280.83292
21719,280.82498
21830,280.98083
21946,281.17566
22052,281.24692
22163,281.3226
22273,281.35919
22381,281.41031
22489,281.41156
22599,281.56607
22709,281.79156
22821,281.98001
22927,281.74524
23026,281.7218
23133,281.87448
23244,282.21048
23355,282.33014
23464,282.17075
23589,282.14288
23694,282.35565
23802,282.50607
23908,282.56357
24012,282.62891
24116,282.77536
24219,282.7756
24325,282.75201
24429,282.84195
24535,283.06839
24641,283.29288
24742,283.16293
24844,283.08514
24977,283.23383
25083,283.46268
25186,283.56705
25289,283.61008
25399,283.69858
25502,283.69894
25601,283.74203
25704,283.79535
25811,284.04498
25921,284.28802
26021,284.12506
26119,284.03342
26219,284.16107
26330,284.46991
26437,284.66266
26537,284.48575
26637,284.491
26739,284.63538
26845,284.81091
26950,284.8255
27054,284.8887
27156,285.10458
27262,285.11923
27363,285.0527
27478,285.08987
27580,285.30078
27687,285.53134
27791,285.51849
27892,285.43018
27995,285.50201
28101,285.71875
28206,285.83667
28310,285.86453
28418,285.95776
28521,285.99359
28622,285.99313
28726,286.05817
28833,286.25098
28943,286.54718
29045,286.43756
29144,286.31583
29247,286.37286
29357,286.67334
29466,286.87149
29567,286.80774
29668,286.75558
29774,286.85934
29882,287.04639
29989,287.04236
30091,287.11694
30197,287.32068
30305,287.40976
30409,287.31631
30539,287.30353
30646,287.51804
30753,287.76865
30859,287.79544
30964,287.65198
31065,287.68536
31170,287.90088
31280,288.07541
31386,288.0784
31490,288.13739
31592,288.20346
31698,288.27939
31801,288.27628
31907,288.43723
32019,288.69772
32123,288.64639
32226,288.50977
32326,288.54056
32436,288.83005
32544,289.06796
32648,289.00662
32801,288.90997
32903,288.98703
33012,289.22113
33115,289.25046
33218,289.27887
33322,289.43704
33430,289.57147
33533,289.49524
33635,289.44244
33741,289.60898
33851,289.88763
33958,289.96994
34080,289.81082
34184,289.78967
34290,289.98114
34399,290.15753
34503,290.23904
34608,290.29263
34714,290.34265
34817,290.35565
34926,290.36215
35033,290.49051
35153,290.75897
35230,290.65262
35266,289.22165
35289,287.42245
35302,286.18332
35311,285.53546
35267,281.71341
35210,277.63397
35157,274.05594
35102,270.36661
35044,266.55438
34986,262.73209
34931,259.21375
34877,255.74561
34817,252.14841
34762,248.52782
34707,245.0575
34651,241.68533
34596,238.18307
34541,234.66347
34487,231.31917
34433,227.93655
34377,224.50076
34321,221.02837
34267,217.75598
34216,214.52429
34162,211.12956
34105,207.61852
34051,204.22966
33999,201.09148
33947,197.8501
33895,194.44318
33839,191.0584
33786,187.84093
33731,184.58568
33678,181.19719
33624,177.9496
33575,174.85291
33522,171.61977
33467,168.29558
33412,164.8775
33363,161.91504
33312,158.92839
33259,155.74457
33204,152.40941
33151,149.15912
33101,146.13861
33053,143.0929
33002,139.97881
32949,136.82651
32897,133.73352
32847,130.64243
32795,127.58678
32749,124.83755
32702,122.01617
32654,119.10448
32603,116.05139
32551,112.98868
32508,110.27235
32460,107.46037
32411,104.51643
32358,101.46964
32312,98.58958
32264,95.75575
32214,92.79285
32165,89.91832
32118,87.15374
32070,84.37984
32021,81.40829
31971,78.27533
31925,75.55175
31879,72.88994
31833,70.09303
31780,67.03279
31729,64.05969
31680,61.33405
31637,58.59289
31589,55.7802
31541,52.91234
31495,50.16608
31447,47.29157
31397,44.37319
31351,41.68158
31306,39.03001
31259,36.33278
31211,33.42618
31162,30.56065
31118,27.9696
31062,25.4965
31017,22.90971
30972,20.18732
30932,17.69624
30891,15.23324
30848,12.69039
30807,10.39055
30774,8.42421
30741,6.38123
30701,4.11363
30691,3.45034
30802,11.29798
30894,18.11106
30992,24.89954
31094,31.78463
31196,38.77691
31296,45.67421
31408,52.75778
31510,59.53238
31620,66.69709
31722,73.43557
31833,80.58429
31941,87.40379
32047,94.28532
32154,101.19034
32262,107.83405
32369,114.56436
32475,121.37625
32573,127.70482
32680,134.21822
32777,140.35643
32879,146.569
32978,152.60457
33077,158.8013
33174,164.77458
33273,170.79919
33376,177.07196
33470,182.8019
33569,188.91925
33666,194.85095
33762,200.59077
33861,206.56497
33960,212.34134
34057,217.97679
34154,223.83405
34250,229.41069
34349,235.09653
34443,240.47475
34557,246.07726
34646,251.25858
34747,256.79428
34841,262.04599
34939,267.16269
35041,272.4548
35141,277.35294
35246,281.95941
35357,286.28818
35470,289.79263
35595,292.7327
35732,294.61404
35892,295.70898
36070,296.0452
36243,296.11499
36421,295.97449
36586,295.53271
36767,295.60001
36938,295.26505
37112,295.28873
37294,295.15314
37473,295.05606
37658,294.97943
37851,295.0022
38044,294.89722
38239,294.91815
38436,294.85648
38637,294.84341
38835,294.70801
39046,294.92056
39251,294.70676
39462,294.89615
39673,294.83932
39884,294.81528
40107,294.96387
40341,294.99344
40563,295.0332
40791,295.17685
41013,295.14029
41235,295.12939
41465,295.2756
41693,295.40329
41924,295.40866
42154,295.57269
42394,295.71732
42617,295.55817
42854,295.93967
43088,295.8172
43321,296.01401
43558,296.15634
43788,296.20117
44022,296.23688
44260,296.41476
44499,296.50714
44739,296.61859
44971,296.78918
45205,296.91467
45434,296.82159
45672,297.16394
45904,297.10596
46135,297.35101
46371,297.49841
46596,297.38223
46832,297.64185
47064,297.73785
47293,297.90225
47524,297.94632
47754,298.16806
47978,298.17999
48209,298.28912
48437,298.41611
48666,298.4899
48890,298.57202
49118,298.86279
49338,298.72754
49564,299.02905
49783,299.02286
50000,299.15735
50223,299.2861
50438,299.38083
50652,299.4809
50868,299.59091
51082,299.70508
51294,299.70139
51514,299.8848
51728,300.04214
51938,300.02237
52146,300.24396
52355,300.26022
52558,300.32214
52772,300.55023
52972,300.53891
53178,300.76404
53382,300.73767
53595,300.97687
53806,300.93619
54009,301.16214
54213,301.17233
54421,301.28137
54623,301.45331
54825,301.47202
55022,301.50323
55227,301.78336
55441,301.6846
55646,301.96753
55854,301.95734
56055,302.02823
56260,302.20261
56463,302.28238
56666,302.40228
56872,302.44281
57078,302.65375
57282,302.59329
57495,302.76804
57729,302.92328
57933,302.7901
58147,303.07739
58362,303.20673
58569,303.10315
58788,303.3887
58998,303.32809
59216,303.50552
59432,303.53836
59645,303.73959
59860,303.6442
60075,303.81454
60294,303.92258
60508,303.90942
60725,304.14648
60945,304.1413
61158,304.14792
61379,304.44296
61594,304.31601
61809,304.46173
62033,304.61203
62249,304.63992
62472,304.77335
62685,304.75482
62910,304.90311
63123,304.85657
63347,305.19449
63574,305.11377
63792,305.17282
64022,305.38211
64240,305.33148
64462,305.42209
64696,305.5939
64913,305.58722
65139,305.80682
65358,305.72006
65583,305.8446
65809,305.84772
66035,306.08798
66263,306.10007
66484,306.12173
66712,306.20639
66931,306.18021
67160,306.43082
67383,306.47156
67602,306.4856
67821,306.64124
68040,306.63879
68261,306.69263
68486,306.83856
68703,306.85388
68926,307.01361
69144,306.98453
69368,307.18347
69585,307.00037
69807,307.32791
70028,307.27493
70246,307.35635
70470,307.55875
70686,307.42227
70906,307.54092
71130,307.70193
71346,307.67218
71572,307.83771
71801,307.82523
72023,307.90744
72241,307.88278
72468,308.09424
72690,308.08871
72904,308.08252
73131,308.35587
73342,308.1452
73567,308.39175
73787,308.46014
74005,308.43546
74239,308.58026
74459,308.64896
74674,308.57312
74898,308.73773
75112,308.772
75332,308.88736
75551,308.85046
75777,309.0957
76002,308.84134
76235,309.11752
76457,309.15973
76672,309.10477
76898,309.36539
77127,309.28439
77346,309.30698
77575,309.44089
77802,309.46802
78027,309.53668
78250,309.60385
78468,309.66714
78691,309.60355
78908,309.73392
79135,309.83154
79351,309.72748
79577,310.03787
79795,309.87335
80018,310.02286
80241,310.05838
80461,310.11316
80682,310.11398
80905,310.25824
81131,310.35507
81355,310.28879
81575,310.37616
81800,310.44504
82019,310.3714
82245,310.6261
82468,310.50806
82688,310.58725
82926,310.67859
83146,310.6192
83374,310.82611
83597,310.75424
83819,310.84537
84043,310.87375
84268,310.95667
84494,310.94333
84717,311.01532
84954,311.0976
85195,311.08444
85421,311.17847
85657,311.29956
85885,311.11243
86116,311.46011
86340,311.22916
86570,311.38721
86798,311.43036
87032,311.43854
87261,311.47064
87492,311.58044
87728,311.58862
87961,311.58975
88190,311.69366
88420,311.75455
88646,311.63763
88880,311.86288
89108,311.75067
89337,311.78268
89575,311.97675
89797,311.79251
90031,312.01474
90262,312.00937
90493,312.03308
90725,312.00452
90956,312.19687
91188,312.14932
91421,312.21375
91653,312.27417
91887,312.22742
92116,312.2135
92356,312.50726
92585,312.27777
92822,312.43246
93066,312.44589
93300,312.46014
93538,312.55096
93772,312.56909
94006,312.56665
94239,312.58023
94476,312.69153
94710,312.61349
94968,312.6615
95222,312.81757
95457,312.73746
95694,312.82486
95933,312.82837
96166,312.72919
96409,313.01355
96641,312.90359
96878,312.91528
97123,312.92593
97373,313.07657
97613,312.94864
97855,313.103
98097,313.15884
98337,313.08438
98575,313.11642
98817,313.21594
99055,313.1322
99299,313.35995
99543,313.2178
99782,313.3349
100025,313.3262
100264,313.3313
100508,313.40811
100746,313.38055
100992,313.53021
101238,313.40042
101482,313.57913
101723,313.40289
101965,313.51221
102209,313.5799
102452,313.50961
102693,313.63638
102948,313.71317
103186,313.53424
103439,313.75967
103682,313.63525
103928,313.79874
104172,313.72705
104415,313.84842
104661,313.70422
104921,313.77597
105171,313.90994
105411,313.76474
105657,313.93344
105905,313.9787
106147,313.81317
106400,314.03793
106645,313.92758
106895,313.97189
107149,314.04468
107390,313.97144
107644,314.06149
107892,314.01086
108146,314.14319
108397,313.98932
108653,314.26529
108901,314.09042
109147,314.03943
109402,314.20013
109658,314.16684
109911,314.14581
110177,314.29276
110424,314.1492
110679,314.26514
110931,314.25372
111185,314.30417
111443,314.20984
111701,314.39261
111956,314.29782
112208,314.23621
112468,314.44293
112722,314.27914
112980,314.43884
113238,314.40552
113491,314.34683
113752,314.40527
114011,314.41455
114269,314.42178
114531,314.50681
114786,314.457
115051,314.51163
115306,314.37546
115582,314.625
115846,314.38278
116110,314.60333
116373,314.51602
116631,314.46613
116900,314.58914
117164,314.5054
117428,314.56833
117697,314.62582
117980,314.57251
118249,314.59491
118520,314.56641
118797,314.64175
119064,314.56461
119335,314.66708
119605,314.60187
119872,314.52982
120149,314.80194
120417,314.52933
120691,314.70273
120970,314.70309
121247,314.63412
121527,314.70969
121810,314.70569
122082,314.6091
122365,314.70731
122641,314.71368
122925,314.74991
123206,314.57312
123488,314.81708
123767,314.612
124052,314.76535
124338,314.76535
124618,314.60843
124910,314.77274
125194,314.7132
125480,314.6965
125772,314.74124
126079,314.68521
126369,314.64999
126662,314.73132
126954,314.7291
127249,314.66254
127539,314.70145
127849,314.73355
128137,314.52661
128444,314.80887
128748,314.60837
129047,314.70502
129349,314.68063
129652,314.66116
129956,314.57413
130264,314.68628
130566,314.65759
130874,314.58301
131178,314.59543
131491,314.63843
131796,314.4838
132110,314.63885
132424,314.535
132737,314.50958
133058,314.56033
133372,314.4895
133692,314.48776
134015,314.45795
134335,314.51419
134657,314.3858
134980,314.436
135305,314.32935
135635,314.29584
135965,314.3949
136295,314.30478
136621,314.23615
136959,314.32278
137290,314.06384
137627,314.26114
137962,314.07797
138302,314.14679
138645,314.08542
138995,314.00903
139339,313.96503
139686,313.92197
140041,313.91681
140391,313.81909
140737,313.83444
141092,313.73895
141443,313.53885
141800,313.63678
142157,313.51328
142510,313.45682
142878,313.52518
143228,313.17682
143592,313.26236
143957,313.1434
144333,313.1283
144699,312.95828
145076,312.96854
145441,312.75821
145811,312.6149
146186,312.5817
146567,312.46646
146936,312.29831
147319,312.37888
147694,311.96814
148074,311.95462
148457,311.79984
148833,311.64221
149226,311.59943
149603,311.35196
149987,311.13232
150378,310.86969
150767,310.88007
151156,310.53577
151555,310.41797
151954,310.26749
152346,309.85251
152739,309.71579
153143,309.47873
153531,309.13263
153940,309.0433
154335,308.61084
154734,308.3736
155138,307.94034
155540,307.86804
155948,307.28409
156350,307.06232
156760,306.70941
157172,306.14645
157580,305.9761
158002,305.41623
158406,304.8959
158836,304.5759
159247,304.00278
159666,303.50766
160097,302.95435
160523,302.43454
160959,301.73761
161385,301.0755
161822,300.60809
162261,299.65109
162699,299.18091
163151,298.13223
163594,297.43491
164056,296.55487
164511,295.51468
164966,294.57474
165444,293.51764
165905,292.34314
166393,291.17163
166867,289.81952
167357,288.47922
167848,286.94324
168339,285.51291
168856,283.52322
169346,281.89188
169869,279.82709
170378,277.59775
170911,275.26691
174727,163.69171